<?xml version="1.0"?>

<robot xmlns:xacro="http://www.ros-org/wiki/xacro" name="myfirst">
    <xacro:property name="width" value="0.2"/>
    <xacro:property name="bodylen" value="0.6"/>
    <xacro:macro name="default_inertial" params="mass *shape">
        <collision>
            <xacro:insert_block name="shape"/>
        </collision>
        <inertial>
            <mass value="${mass}"/>
            <inertia ixx="1e-3" ixy="0.0" ixz="0.0" iyy="1e-3" iyz="0.0" izz="1e-3"/>
        </inertial>
    </xacro:macro>

    <material name="white">
        <color rgba="1 1 1 1"/>
    </material>

    <material name="blue">
        <color rgba="0 0 0.8 1"/>
    </material>

    <material name="black">
        <color rgba="0 0 0 1"/>
    </material>

    <link name="base_link">
        <visual>
            <geometry>
                <cylinder length="${bodylen}" radius="${width}" />
            </geometry>
            <material name="blue"/>
        </visual>
        <xacro:default_inertial mass="10">
            <geometry>
                <cylinder length="${bodylen}" radius="${width}" />
            </geometry>
        </xacro:default_inertial>
    </link>

    <link name="right_leg">
        <visual>
            <geometry>
                <box size="0.6 0.1 0.2" />
            </geometry>
            <origin rpy="0 1.57 0" xyz="0 0 -0.3"/>
            <material name="white"/>
        </visual>
        <xacro:default_inertial mass="1">
            <geometry>
                <box size="0.6 0.1 0.2" />
            </geometry>
        </xacro:default_inertial>
    </link>

    <link name="right_front_wheel">
        <visual>
            <geometry>
                <cylinder length="0.1" radius="0.035"/>
            </geometry>
            <origin rpy="1.57 0 0" xyz="0 0 0"/>
            <material name="black"/>
        </visual>
        <xacro:default_inertial mass="1">
            <geometry>
                <cylinder length="0.1" radius="0.035"/>
            </geometry>
        </xacro:default_inertial>
    </link>

    <joint name="right_front_wheel_joint" type="continuous">
        <axis rpy="0 0 0" xyz="0 1 0"/>
        <parent link="right_leg"/>
        <child link= "right_front_wheel"/>
        <origin xyz="0 0 -0.65"/>
    </joint>

    <joint name="base_to_right_leg" type="fixed">
        <parent link="base_link"/>
        <child link= "right_leg"/>
        <origin xyz="0 -0.22 0.25"/>
    </joint>

    <link name="left_leg">
        <visual>
            <geometry>
                <box size="0.6 0.1 0.2" />
            </geometry>
            <origin rpy="0 1.57 0" xyz="0 0 -0.3"/>
            <material name="white"/>
        </visual>
        <xacro:default_inertial mass="10">
            <geometry>
                <box size="0.6 0.1 0.2" />
            </geometry>
        </xacro:default_inertial>
    </link>

    <link name="left_front_wheel">
        <visual>
            <geometry>
                <cylinder length="0.1" radius="0.035"/>
            </geometry>
            <origin rpy="1.57 0 0" xyz="0 0 0"/>
            <material name="black"/>
        </visual>
        <xacro:default_inertial mass="1">
            <geometry>
                <cylinder length="0.1" radius="0.035"/>
            </geometry>
        </xacro:default_inertial>
    </link>

    <joint name="left_front_wheel_joint" type="continuous">
        <axis rpy="0 0 0" xyz="0 1 0"/>
        <parent link="left_leg"/>
        <child link= "left_front_wheel"/>
        <origin xyz="0 0 -0.65"/>
    </joint>

    <joint name="base_to_left_leg" type="fixed">
        <parent link="base_link"/>
        <child link= "left_leg"/>
        <origin xyz="0 0.22 0.25"/>
    </joint>

</robot>