<sdf version='1.7'>
    <model name='myfirst'>
        <link name='base_link'>
            <inertial>
                <pose>0 0 0.166667 0 -0 0</pose>
                <mass>30</mass>
                <inertia>
                    <ixx>1.38767</ixx>
                    <ixy>0</ixy>
                    <ixz>0</ixz>
                    <iyy>0.419667</iyy>
                    <iyz>0</iyz>
                    <izz>0.971</izz>
                </inertia>
            </inertial>
            <collision name='base_link_collision'>
                <pose>0 0 0 0 -0 0</pose>
                <geometry>
                    <cylinder>
                        <length>0.6</length>
                        <radius>0.2</radius>
                    </cylinder>
                </geometry>
            </collision>
            <collision name='base_link_fixed_joint_lump__left_leg_collision_1'>
                <pose>0 0.22 -0.05 0 1.5708 0</pose>
                <geometry>
                    <box>
                        <size>0.6 0.1 0.2</size>
                    </box>
                </geometry>
            </collision>
            <collision name='base_link_fixed_joint_lump__right_leg_collision_2'>
                <pose>0 -0.22 -0.05 0 1.5708 0</pose>
                <geometry>
                    <box>
                        <size>0.6 0.1 0.2</size>
                    </box>
                </geometry>
            </collision>
            <visual name='base_link_visual'>
                <pose>0 0 0 0 -0 0</pose>
                <geometry>
                    <cylinder>
                        <length>0.6</length>
                        <radius>0.2</radius>
                    </cylinder>
                </geometry>
            </visual>
            <visual name='base_link_fixed_joint_lump__left_leg_visual_1'>
                <pose>0 0.22 -0.05 0 1.5708 0</pose>
                <geometry>
                    <box>
                        <size>0.6 0.1 0.2</size>
                    </box>
                </geometry>
            </visual>
            <visual name='base_link_fixed_joint_lump__right_leg_visual_2'>
                <pose>0 -0.22 -0.05 0 1.5708 0</pose>
                <geometry>
                    <box>
                        <size>0.6 0.1 0.2</size>
                    </box>
                </geometry>
            </visual>
        </link>
        <joint name='left_front_wheel_joint' type='revolute'>
            <pose relative_to='base_link'>0 0.22 -0.4 0 -0 0</pose>
            <parent>base_link</parent>
            <child>left_front_wheel</child>
            <axis>
                <xyz>0 1 0</xyz>
                <limit>
                    <lower>-1e+16</lower>
                    <upper>1e+16</upper>
                </limit>
                <dynamics>
                    <spring_reference>0</spring_reference>
                    <spring_stiffness>0</spring_stiffness>
                </dynamics>
            </axis>
        </joint>
        <link name='left_front_wheel'>
            <pose relative_to='left_front_wheel_joint'>0 0 0 0 -0 0</pose>
            <inertial>
                <pose>0 0 0 0 -0 0</pose>
                <mass>1</mass>
                <inertia>
                    <ixx>0.001</ixx>
                    <ixy>0</ixy>
                    <ixz>0</ixz>
                    <iyy>0.001</iyy>
                    <iyz>0</iyz>
                    <izz>0.001</izz>
                </inertia>
            </inertial>
            <collision name='left_front_wheel_collision'>
                <pose>0 0 0 1.57 -0 0</pose>
                <geometry>
                    <cylinder>
                        <length>0.1</length>
                        <radius>0.035</radius>
                    </cylinder>
                </geometry>
            </collision>
            <visual name='left_front_wheel_visual'>
                <pose>0 0 0 1.57 -0 0</pose>
                <geometry>
                    <cylinder>
                        <length>0.1</length>
                        <radius>0.035</radius>
                    </cylinder>
                </geometry>
            </visual>
        </link>
        <joint name='right_front_wheel_joint' type='revolute'>
            <pose relative_to='base_link'>0 -0.22 -0.4 0 -0 0</pose>
            <parent>base_link</parent>
            <child>right_front_wheel</child>
            <axis>
                <xyz>0 1 0</xyz>
                <limit>
                    <lower>-1e+16</lower>
                    <upper>1e+16</upper>
                </limit>
                <dynamics>
                    <spring_reference>0</spring_reference>
                    <spring_stiffness>0</spring_stiffness>
                </dynamics>
            </axis>
        </joint>
        <link name='right_front_wheel'>
            <pose relative_to='right_front_wheel_joint'>0 0 0 0 -0 0</pose>
            <inertial>
                <pose>0 0 0 0 -0 0</pose>
                <mass>1</mass>
                <inertia>
                    <ixx>0.001</ixx>
                    <ixy>0</ixy>
                    <ixz>0</ixz>
                    <iyy>0.001</iyy>
                    <iyz>0</iyz>
                    <izz>0.001</izz>
                </inertia>
            </inertial>
            <collision name='right_front_wheel_collision'>
                <pose>0 0 0 1.57 -0 0</pose>
                <geometry>
                    <cylinder>
                        <length>0.1</length>
                        <radius>0.035</radius>
                    </cylinder>
                </geometry>
            </collision>
            <visual name='right_front_wheel_visual'>
                <pose>0 0 0 1.57 -0 0</pose>
                <geometry>
                    <cylinder>
                        <length>0.1</length>
                        <radius>0.035</radius>
                    </cylinder>
                </geometry>
            </visual>
        </link>
    </model>
</sdf>