<?xml version="1.0"?>
<!-- ros2 launch ku_description display.launch.py model:=urdf/visual.urdf -->
<robot name="myfirst">
    <material name="white">
        <color rgba="1 1 1 1"/>
    </material>

    <material name="blue">
        <color rgba="0 0 0.8 1"/>
    </material>

    <material name="black">
        <color rgba="0 0 0 1"/>
    </material>

    <link name="base_link">
        <visual>
            <geometry>
                <cylinder length="0.6" radius="0.2" />
            </geometry>
            <material name="blue"/>
        </visual>
    </link>

    <link name="right_leg">
        <visual>
            <geometry>
                <box size="0.6 0.1 0.2" />
            </geometry>
            <origin rpy="0 1.57 0" xyz="0 0 -0.3"/>
            <material name="white"/>
        </visual>
    </link>

    <link name="right_front_wheel">
        <visual>
            <geometry>
                <cylinder length="0.1" radius="0.035"/>
            </geometry>
            <origin rpy="1.57 0 0" xyz="0 0 0"/>
            <material name="black"/>
        </visual>
    </link>

    <joint name="right_front_wheel_joint" type="continuous">
        <parent link="right_leg"/>
        <child link= "right_front_wheel"/>
        <origin xyz="0 0 -0.65"/>
    </joint>

    <joint name="base_to_right_leg" type="fixed">
        <parent link="base_link"/>
        <child link= "right_leg"/>
        <origin xyz="0 -0.22 0.25"/>
    </joint>

    <link name="left_leg">
        <visual>
            <geometry>
                <box size="0.6 0.1 0.2" />
            </geometry>
            <origin rpy="0 1.57 0" xyz="0 0 -0.3"/>
            <material name="white"/>
        </visual>
    </link>

    <joint name="base_to_left_leg" type="fixed">
        <parent link="base_link"/>
        <child link= "left_leg"/>
        <origin xyz="0 0.22 0.25"/>
    </joint>

</robot>